# promise

在实际的使用中，有非常多的应用场景我们不能立即知道应该如何继续往下执行。最常见的一个场景就是 ajax 请求。通俗来说，由于网速的不同，可能你得到返回值的时间也是不同的，这个时候我们就需要等待，结果出来了之后才知道怎么样继续下去。

## 一、 Promise 对象有三种状态，他们分别是

pending: 等待中，或者进行中，表示还没有得到结果
resolved(Fulfilled): 已经完成，表示得到了我们想要的结果，可以继续往下执行
rejected: 也表示得到结果，但是由于结果并非我们所愿，因此拒绝执行

## 二、 then

Promise 对象中的 then 方法，可以接收构造函数中处理的状态变化，并分别对应执行。then 方法有 2 个参数，第一个函数接收 resolved 状态的执行，第二个参数接收 reject 状态的执行。

## 三、Promise 中的数据传递

```js
var fn = function (num) {
  return new Promise(function (resolve, reject) {
    if (typeof num == "number") {
      resolve(num);
    } else {
      reject("TypeError");
    }
  });
};

fn(2)
  .then(function (num) {
    console.log("first: " + num);
    return num + 1;
  })
  .then(function (num) {
    console.log("second: " + num);
    return num + 1;
  })
  .then(function (num) {
    console.log("third: " + num);
    return num + 1;
  });

// 输出结果
first: 2;
second: 3;
third: 4;
```

## 四、Promise.all

所有子 Promise 完成，则该 Promise 完成，并且返回值是参数数组中所有 Promise 实例的结果组成的数组
有任何一个 Promise 失败，则该 Promise 失败，返回值是第一个失败的 Promise 的结果

## 五、 Promise.race

与 Promise.all 相似的是，Promise.race 都是以一个 Promise 对象组成的数组作为参数，不同的是，只要当数组中的其中一个 Promsie 状态变成 resolved 或者 rejected 时，就可以调用.then 方法了。而传递给 then 方法的值也会有所不同

传入的数组中有一个 Promise 完成了则整个 Promise 完成了。

## 六、特点

（1）对象的状态不受外界影响。Promise 对象代表一个异步操作，有三种状态：pending（进行中）、fulfilled（已成功）和 rejected（已失败）。

（2）一旦状态改变，就不会再变，任何时候都可以得到这个结果。Promise 对象的状态改变，只有两种可能：从 pending 变为 fulfilled 和从 pending 变为 rejected。

有了 Promise 对象，就可以将异步操作以同步操作的流程表达出来，避免了层层嵌套的回调函数。此外，Promise 对象提供统一的接口，使得控制异步操作更加容易。

## 七、缺点

首先，无法取消 Promise，一旦新建它就会立即执行，无法中途取消。
其次，如果不设置回调函数，Promise 内部抛出的错误，不会反应到外部。
第三，当处于 pending 状态时，无法得知目前进展到哪一个阶段（刚刚开始还是即将完成）。

## 八、Promise 执行顺序

1、

```js
const promise = new Promise((resolve, reject) => {
  console.log(1);
  resolve();
  console.log(2);
});
promise.then(() => {
  console.log(4);
});
console.log(5);
```

运行结果是： 1,2,5,4

解释：promise 的构造函数是同步执行，promise.then 中的函数是异步执行。

2、

```js
const promise = new Promise((resolve, reject) => {
  resolve("success1");
  reject("error");
  resolve("success2");
});
promise
  .then((res) => {
    console.log("then: ", res);
  })
  .catch((err) => {
    console.log("catch: ", err);
  });
```

运行结果：then: success1

解释：构造函数中的 resolve 或 reject 只有第一次执行有效，多次调用没有任何作用。promise 状态一旦改变则不能再变。 promise 有 3 种状 态： pending、fulfilled 或 rejected。 状态改变只能是 pending->fulfilled 或者 pending-> rejected，状态一旦改变则不能再变。

3、

```js
const promise = new Promise((resolve, reject) => {
  setTimeout(() => {
    console.log("once");
    resolve("success");
  }, 1000);
});
const start = Date.now();
promise.then((res) => {
  console.log(res, Date.now() - start);
});
promise.then((res) => {
  console.log(res, Date.now() - start);
});
```

运行结果： once success 1005 success 1007

解释：promise 的 .then 或者 .catch 可以被调用多次，但这里 Promise 构造函数只执行一次。或者说 promise 内部状态一经改变，并且有了一个值，那么后续每次调用 .then 或者 .catch 都会直接拿到该值。

4、

```js
console.log("start");
new Promise(function (resolve, reject) {
  setTimeout(function () {
    //定时器模拟异步
    resolve("hello"); //修改 promise 状态调用 then 中的第一个函数
  }, 2000);
})
  .then((value) => {
    console.log(value); //接收 resolve 传来的值
    return new Promise(function (resolve) {
      //该 then()返回一个新的 promise 实例，后面可以继续接 then
      setTimeout(function () {
        resolve("world"); //修改新 promise 的状态，去调用 then
      }, 3000);
    });
  })
  .then((value) => {
    console.log(value);
  });

//输出结果： /_ 立即输出 start 两秒输出 hello 再三秒 world _/
```

5、上面我们在 then() 函数中返回的是一个新的 promise，如果返回的不是一个新的 promise 会怎样呢？依然是上面的代码，稍作修改。

```js
console.log('start');
new Promise(function(resolve,reject){
    setTimeout(function(){
    resolve('hello');
    },2000);
}).then((value)=>{
    console.log(value);
    (function(){
        return new Promise(function(resolve){
        setTimeout(function(){
            resolve('world');
        },3000)
        })
    })();
    return false;
}).then((value)=>{
    console.log(value);
})

/_ 结果： 立即输出 start 两秒输出 hello 三秒输出 false _/
```

根据上面的运行结果来看，**如果在一个 then（）中没有返回一个新的 promise，则 return 什么下一个 then 就接受什么**，在上面的实例代码中 return 的是 false，下一个 then 中接受到的 value 就是 false，如果 then 中没有 return，则默认 return 的是 undefined.

6、then（）中包含.then（）的嵌套情况 then()的嵌套会先将内部的 then()执行完毕再继续执行外部的 then();在多个 then 嵌套时建议将其展开，将 then()放在同一级，这样代码更清晰。

```js
console.log('start');
new Promise((resolve,reject)=>{
    setTimeout(function(){
        console.log('step');
        resolve(110);
    },1000)
})
.then((value)=>{
    return new Promise((resolve,reject)=>{
        setTimeout(function(){
            console.log('step1');
            resolve(value);
        },1000)
    })
    .then((value)=>{
        console.log('step 1-1');
        return value;
    })
    .then((value)=>{
        console.log('step 1-2');
        return value;
    })
})
.then((value)=>{
    console.log(value);
    console.log('step 2');
})
/_ start step step1 step 1-1 step 1-2 110 step 2 _/

//展开之后的代码
console.log('start');
new Promise((resolve,reject)=>{
    setTimeout(function(){
        console.log('step');
        resolve(110);
    },1000)
})
.then((value)=>{
    return new Promise((resolve,reject)=>{
        setTimeout(function(){
            console.log('step1');
            resolve(value);
        },1000)
    })
})
.then((value)=>{
    console.log('step 1-1');
    return value;
})
.then((value)=>{
    console.log('step 1-2');
    return value;
})
.then((value)=>{
    console.log(value);
    console.log('step 2');
})
```

7、catch 和 then 的连用 如果每一步都有可能出现错误，那么就可能出现 catch 后面接上 then 的情况。上代码

```js
new Promise((resolve,reject)=>{
    resolve();
})
.then(value=>{
    console.log('done 1');
    throw new Error('done 1 error');
})
.catch(err=>{
    console.log('错误信息 1：'+err);
})
.then(value=>{
    console.log('done 2');
})
.catch(err=>{
    console.log('错误信息 2：'+err);
})
/_ done 1 错误信息 1：Error: done 1 error done 2 说明 catch 后面会继续执行 then，catch 返回的也是一个 promise 实例 _/
new Promise((resolve,reject)=>{
    resolve();
})
.then(value=>{
    console.log('done 1');
    throw new Error('done 1 error');
})
.catch(err=>{
    console.log('错误信息 1：'+err);
    throw new Error('catch error');
})
.then(value=>{
    console.log('done 2');
})
.catch(err=>{
    console.log('错误信息 2：'+err);
})
/\* done 1 错误信息 1：Error: done 1 error 错误信息 2：Error: catch error 如果在 catch 中也抛出了错误，则后面的 then 的第一个函数不会执行，因为返回的 promise 状态已经为 rejected 了
```

8、Promise.all() 将多个 Promise 批量执行，所有的 Promise 都完毕之后返回一个新的 Promise

1、接收一个数组作为参数
2、数组中可以是 Promise 实例，也可以是别的值，只有 Promise 会等待状态的改变
3、所有子 Promise 完成，则该 Promise 完成，并且返回值是参数数组中所有 Promise 实
例的结果组成的数组
4、有任何一个 Promise 失败，则该 Promise 失败，返回值是第一个失败的 Promise 的结果

```js
console.log("here we go");
Promise.all([1, 2, 3])
  .then((all) => {
    console.log("1: " + all);
    return Promise.all([
      function () {
        console.log("ooxx");
      },
      "xxoo",
      false,
    ]);
  })
  .then((all) => {
    console.log("2: " + all);
    let p1 = new Promise((resolve) => {
      setTimeout(function () {
        resolve("I'm p1");
      }, 1500);
    });
    let p2 = new Promise((resolve) => {
      setTimeout(function () {
        resolve("I'm p2");
      }, 2000);
    });
    return Promise.all([p1, p2]);
  })
  .then((all) => {
    console.log("3: " + all);
    let p1 = new Promise((resolve, reject) => {
      setTimeout(function () {
        resolve("P1");
      }, 1000);
    });
    let p2 = new Promise((resolve, reject) => {
      setTimeout(function () {
        reject("P2");
      }, 3000);
    });
    let p3 = new Promise((resolve, reject) => {
      setTimeout(function () {
        reject("P3");
      }, 2000);
    });
    return Promise.all([p1, p2, p3]);
  })
  .then((all) => {
    console.log("all: " + all);
  })
  .catch((err) => {
    console.log("Catch:" + err);
  });
/* here we go 1: 1,2,3 2: function(){ console.log('ooxx'); },xxoo,false 3: I'm p1,I'm p2 Catch:P3 证明了上面的四点。 */
```

9、Promise.race() 和 Promise.all()差不多，区别就是传入的数组中有一个 Promise 完成了则整个 Promise 完成了。

```js
let p1 = new Promise((resolve) => {
  setTimeout(function () {
    resolve("p1");
  }, 10000);
});
let p2 = new Promise((resolve) => {
  setTimeout(function () {
    resolve("p2");
  }, 1000);
});
Promise.race([p1, p2]).then((value) => {
  console.log(value);
});
/* p1 1s之后输出 。。 等待十秒后代码才算执行完毕 */
```
